[2025-05-20T13:24:27.392+0000] {local_task_job_runner.py:123} INFO - ::group::Pre task execution logs
[2025-05-20T13:24:27.409+0000] {taskinstance.py:2631} INFO - Dependencies all met for dep_context=non-requeueable deps ti=<TaskInstance: my_first_dbt_model.dbt_run scheduled__2025-05-19T00:00:00+00:00 [queued]>
[2025-05-20T13:24:27.415+0000] {taskinstance.py:2631} INFO - Dependencies all met for dep_context=requeueable deps ti=<TaskInstance: my_first_dbt_model.dbt_run scheduled__2025-05-19T00:00:00+00:00 [queued]>
[2025-05-20T13:24:27.416+0000] {taskinstance.py:2884} INFO - Starting attempt 1 of 1
[2025-05-20T13:24:27.475+0000] {taskinstance.py:2907} INFO - Executing <Task(BashOperator): dbt_run> on 2025-05-19 00:00:00+00:00
[2025-05-20T13:24:27.485+0000] {warnings.py:112} WARNING - /home/***/.local/lib/python3.12/site-packages/***/task/task_runner/standard_task_runner.py:70: DeprecationWarning: This process (pid=87) is multi-threaded, use of fork() may lead to deadlocks in the child.
  pid = os.fork()

[2025-05-20T13:24:27.487+0000] {standard_task_runner.py:72} INFO - Started process 92 to run task
[2025-05-20T13:24:27.486+0000] {standard_task_runner.py:104} INFO - Running: ['***', 'tasks', 'run', 'my_first_dbt_model', 'dbt_run', 'scheduled__2025-05-19T00:00:00+00:00', '--job-id', '13', '--raw', '--subdir', 'DAGS_FOLDER/dag_first_model.py', '--cfg-path', '/tmp/tmpbk2f10tx']
[2025-05-20T13:24:27.488+0000] {standard_task_runner.py:105} INFO - Job 13: Subtask dbt_run
[2025-05-20T13:24:27.578+0000] {task_command.py:467} INFO - Running <TaskInstance: my_first_dbt_model.dbt_run scheduled__2025-05-19T00:00:00+00:00 [running]> on host 7f3841fb9e82
[2025-05-20T13:24:27.764+0000] {taskinstance.py:3157} INFO - Exporting env vars: AIRFLOW_CTX_DAG_OWNER='***' AIRFLOW_CTX_DAG_ID='my_first_dbt_model' AIRFLOW_CTX_TASK_ID='dbt_run' AIRFLOW_CTX_EXECUTION_DATE='2025-05-19T00:00:00+00:00' AIRFLOW_CTX_TRY_NUMBER='1' AIRFLOW_CTX_DAG_RUN_ID='scheduled__2025-05-19T00:00:00+00:00'
[2025-05-20T13:24:27.765+0000] {logging_mixin.py:190} INFO - Task instance is in running state
[2025-05-20T13:24:27.765+0000] {logging_mixin.py:190} INFO -  Previous state of the Task instance: queued
[2025-05-20T13:24:27.766+0000] {logging_mixin.py:190} INFO - Current task name:dbt_run state:running start_date:2025-05-20 13:24:27.410231+00:00
[2025-05-20T13:24:27.766+0000] {logging_mixin.py:190} INFO - Dag name:my_first_dbt_model and current dag run status:running
[2025-05-20T13:24:27.766+0000] {taskinstance.py:740} INFO - ::endgroup::
[2025-05-20T13:24:27.767+0000] {subprocess.py:78} INFO - Tmp dir root location: /tmp
[2025-05-20T13:24:27.768+0000] {subprocess.py:88} INFO - Running command: ['/usr/bin/bash', '-c', 'cd /opt/***/dbt_model && dbt run -m my_first_dbt_model']
[2025-05-20T13:24:27.781+0000] {subprocess.py:99} INFO - Output:
[2025-05-20T13:24:27.783+0000] {subprocess.py:106} INFO - /usr/bin/bash: line 1: cd: /opt/***/dbt_model: No such file or directory
[2025-05-20T13:24:27.783+0000] {subprocess.py:110} INFO - Command exited with return code 1
[2025-05-20T13:24:27.796+0000] {taskinstance.py:3336} ERROR - Task failed with exception
Traceback (most recent call last):
  File "/home/airflow/.local/lib/python3.12/site-packages/airflow/models/taskinstance.py", line 776, in _execute_task
    result = _execute_callable(context=context, **execute_callable_kwargs)
             ^^^^^^^^^^^^^^^^^^^^^^^^^^^^^^^^^^^^^^^^^^^^^^^^^^^^^^^^^^^^^
  File "/home/airflow/.local/lib/python3.12/site-packages/airflow/models/taskinstance.py", line 742, in _execute_callable
    return ExecutionCallableRunner(
           ^^^^^^^^^^^^^^^^^^^^^^^^
  File "/home/airflow/.local/lib/python3.12/site-packages/airflow/utils/operator_helpers.py", line 252, in run
    return self.func(*args, **kwargs)
           ^^^^^^^^^^^^^^^^^^^^^^^^^^
  File "/home/airflow/.local/lib/python3.12/site-packages/airflow/models/baseoperator.py", line 424, in wrapper
    return func(self, *args, **kwargs)
           ^^^^^^^^^^^^^^^^^^^^^^^^^^^
  File "/home/airflow/.local/lib/python3.12/site-packages/airflow/operators/bash.py", line 276, in execute
    raise AirflowException(
airflow.exceptions.AirflowException: Bash command failed. The command returned a non-zero exit code 1.
[2025-05-20T13:24:27.801+0000] {logging_mixin.py:190} INFO - Task instance in failure state
[2025-05-20T13:24:27.802+0000] {logging_mixin.py:190} INFO - Task start:2025-05-20 13:24:27.410231+00:00 end:2025-05-20 13:24:27.801249+00:00 duration:0.391018
[2025-05-20T13:24:27.802+0000] {logging_mixin.py:190} INFO - Task:<Task(BashOperator): dbt_run> dag:<DAG: my_first_dbt_model> dagrun:<DagRun my_first_dbt_model @ 2025-05-19 00:00:00+00:00: scheduled__2025-05-19T00:00:00+00:00, state:running, queued_at: 2025-05-20 13:24:22.925165+00:00. externally triggered: False>
[2025-05-20T13:24:27.802+0000] {logging_mixin.py:190} INFO - Failure caused by Bash command failed. The command returned a non-zero exit code 1.
[2025-05-20T13:24:27.803+0000] {taskinstance.py:1242} INFO - Marking task as FAILED. dag_id=my_first_dbt_model, task_id=dbt_run, run_id=scheduled__2025-05-19T00:00:00+00:00, execution_date=20250519T000000, start_date=20250520T132427, end_date=20250520T132427
[2025-05-20T13:24:27.908+0000] {taskinstance.py:349} INFO - ::group::Post task execution logs
[2025-05-20T13:24:27.909+0000] {standard_task_runner.py:124} ERROR - Failed to execute job 13 for task dbt_run (Bash command failed. The command returned a non-zero exit code 1.; 92)
Traceback (most recent call last):
  File "/home/airflow/.local/lib/python3.12/site-packages/airflow/task/task_runner/standard_task_runner.py", line 117, in _start_by_fork
    ret = args.func(args, dag=self.dag)
          ^^^^^^^^^^^^^^^^^^^^^^^^^^^^^
  File "/home/airflow/.local/lib/python3.12/site-packages/airflow/cli/cli_config.py", line 49, in command
    return func(*args, **kwargs)
           ^^^^^^^^^^^^^^^^^^^^^
  File "/home/airflow/.local/lib/python3.12/site-packages/airflow/utils/cli.py", line 116, in wrapper
    return f(*args, **kwargs)
           ^^^^^^^^^^^^^^^^^^
  File "/home/airflow/.local/lib/python3.12/site-packages/airflow/cli/commands/task_command.py", line 483, in task_run
    task_return_code = _run_task_by_selected_method(args, _dag, ti)
                       ^^^^^^^^^^^^^^^^^^^^^^^^^^^^^^^^^^^^^^^^^^^^
  File "/home/airflow/.local/lib/python3.12/site-packages/airflow/cli/commands/task_command.py", line 256, in _run_task_by_selected_method
    return _run_raw_task(args, ti)
           ^^^^^^^^^^^^^^^^^^^^^^^
  File "/home/airflow/.local/lib/python3.12/site-packages/airflow/cli/commands/task_command.py", line 341, in _run_raw_task
    return ti._run_raw_task(
           ^^^^^^^^^^^^^^^^^
  File "/home/airflow/.local/lib/python3.12/site-packages/airflow/utils/session.py", line 97, in wrapper
    return func(*args, session=session, **kwargs)
           ^^^^^^^^^^^^^^^^^^^^^^^^^^^^^^^^^^^^^^
  File "/home/airflow/.local/lib/python3.12/site-packages/airflow/models/taskinstance.py", line 3029, in _run_raw_task
    return _run_raw_task(
           ^^^^^^^^^^^^^^
  File "/home/airflow/.local/lib/python3.12/site-packages/airflow/models/taskinstance.py", line 282, in _run_raw_task
    TaskInstance._execute_task_with_callbacks(
  File "/home/airflow/.local/lib/python3.12/site-packages/airflow/models/taskinstance.py", line 3184, in _execute_task_with_callbacks
    result = self._execute_task(context, task_orig)
             ^^^^^^^^^^^^^^^^^^^^^^^^^^^^^^^^^^^^^^
  File "/home/airflow/.local/lib/python3.12/site-packages/airflow/models/taskinstance.py", line 3208, in _execute_task
    return _execute_task(self, context, task_orig)
           ^^^^^^^^^^^^^^^^^^^^^^^^^^^^^^^^^^^^^^^
  File "/home/airflow/.local/lib/python3.12/site-packages/airflow/models/taskinstance.py", line 776, in _execute_task
    result = _execute_callable(context=context, **execute_callable_kwargs)
             ^^^^^^^^^^^^^^^^^^^^^^^^^^^^^^^^^^^^^^^^^^^^^^^^^^^^^^^^^^^^^
  File "/home/airflow/.local/lib/python3.12/site-packages/airflow/models/taskinstance.py", line 742, in _execute_callable
    return ExecutionCallableRunner(
           ^^^^^^^^^^^^^^^^^^^^^^^^
  File "/home/airflow/.local/lib/python3.12/site-packages/airflow/utils/operator_helpers.py", line 252, in run
    return self.func(*args, **kwargs)
           ^^^^^^^^^^^^^^^^^^^^^^^^^^
  File "/home/airflow/.local/lib/python3.12/site-packages/airflow/models/baseoperator.py", line 424, in wrapper
    return func(self, *args, **kwargs)
           ^^^^^^^^^^^^^^^^^^^^^^^^^^^
  File "/home/airflow/.local/lib/python3.12/site-packages/airflow/operators/bash.py", line 276, in execute
    raise AirflowException(
airflow.exceptions.AirflowException: Bash command failed. The command returned a non-zero exit code 1.
[2025-05-20T13:24:27.945+0000] {local_task_job_runner.py:266} INFO - Task exited with return code 1
[2025-05-20T13:24:27.984+0000] {taskinstance.py:3924} INFO - 0 downstream tasks scheduled from follow-on schedule check
[2025-05-20T13:24:28.053+0000] {local_task_job_runner.py:245} INFO - ::endgroup::
